> python manage.py migrate                                                                                         
Operations to perform:
  Apply all migrations: account, admin, auth, authtoken, contenttypes, django_celery_beat, sessions, sites, socialaccount, users
Running migrations:
  Applying account.0001_initial...Traceback (most recent call last):
  File "/Users/arexils/Library/Caches/pypoetry/virtualenvs/django-kttZJNBW-py3.11/lib/python3.11/site-packages/django/db/backends/utils.py", line 87, in _execute
    return self.cursor.execute(sql)
           ^^^^^^^^^^^^^^^^^^^^^^^^
  File "/Users/arexils/Library/Caches/pypoetry/virtualenvs/django-kttZJNBW-py3.11/lib/python3.11/site-packages/django/db/backends/mysql/base.py", line 75, in execute
    return self.cursor.execute(query, args)
           ^^^^^^^^^^^^^^^^^^^^^^^^^^^^^^^^
  File "/Users/arexils/Library/Caches/pypoetry/virtualenvs/django-kttZJNBW-py3.11/lib/python3.11/site-packages/MySQLdb/cursors.py", line 206, in execute
    res = self._query(query)
          ^^^^^^^^^^^^^^^^^^
  File "/Users/arexils/Library/Caches/pypoetry/virtualenvs/django-kttZJNBW-py3.11/lib/python3.11/site-packages/MySQLdb/cursors.py", line 319, in _query
    db.query(q)
  File "/Users/arexils/Library/Caches/pypoetry/virtualenvs/django-kttZJNBW-py3.11/lib/python3.11/site-packages/MySQLdb/connections.py", line 254, in query
    _mysql.connection.query(self, query)
MySQLdb.OperationalError: (1050, "Table 'account_emailaddress' already exists")

The above exception was the direct cause of the following exception:

Traceback (most recent call last):
  File "/Users/arexils/Other/Programming/my_project/django/manage.py", line 31, in <module>
    execute_from_command_line(sys.argv)
  File "/Users/arexils/Library/Caches/pypoetry/virtualenvs/django-kttZJNBW-py3.11/lib/python3.11/site-packages/django/core/management/__init__.py", line 446, in execute_from_command_line
    utility.execute()
  File "/Users/arexils/Library/Caches/pypoetry/virtualenvs/django-kttZJNBW-py3.11/lib/python3.11/site-packages/django/core/management/__init__.py", line 440, in execute
    self.fetch_command(subcommand).run_from_argv(self.argv)
  File "/Users/arexils/Library/Caches/pypoetry/virtualenvs/django-kttZJNBW-py3.11/lib/python3.11/site-packages/django/core/management/base.py", line 402, in run_from_argv
    self.execute(*args, **cmd_options)
  File "/Users/arexils/Library/Caches/pypoetry/virtualenvs/django-kttZJNBW-py3.11/lib/python3.11/site-packages/django/core/management/base.py", line 448, in execute
    output = self.handle(*args, **options)
             ^^^^^^^^^^^^^^^^^^^^^^^^^^^^^
  File "/Users/arexils/Library/Caches/pypoetry/virtualenvs/django-kttZJNBW-py3.11/lib/python3.11/site-packages/django/core/management/base.py", line 96, in wrapped
    res = handle_func(*args, **kwargs)
          ^^^^^^^^^^^^^^^^^^^^^^^^^^^^
  File "/Users/arexils/Library/Caches/pypoetry/virtualenvs/django-kttZJNBW-py3.11/lib/python3.11/site-packages/django/core/management/commands/migrate.py", line 349, in handle
    post_migrate_state = executor.migrate(
                         ^^^^^^^^^^^^^^^^^
  File "/Users/arexils/Library/Caches/pypoetry/virtualenvs/django-kttZJNBW-py3.11/lib/python3.11/site-packages/django/db/migrations/executor.py", line 135, in migrate
    state = self._migrate_all_forwards(
            ^^^^^^^^^^^^^^^^^^^^^^^^^^^
  File "/Users/arexils/Library/Caches/pypoetry/virtualenvs/django-kttZJNBW-py3.11/lib/python3.11/site-packages/django/db/migrations/executor.py", line 167, in _migrate_all_forwards
    state = self.apply_migration(
            ^^^^^^^^^^^^^^^^^^^^^
  File "/Users/arexils/Library/Caches/pypoetry/virtualenvs/django-kttZJNBW-py3.11/lib/python3.11/site-packages/django/db/migrations/executor.py", line 252, in apply_migration
    state = migration.apply(state, schema_editor)
            ^^^^^^^^^^^^^^^^^^^^^^^^^^^^^^^^^^^^^
  File "/Users/arexils/Library/Caches/pypoetry/virtualenvs/django-kttZJNBW-py3.11/lib/python3.11/site-packages/django/db/migrations/migration.py", line 130, in apply
    operation.database_forwards(
  File "/Users/arexils/Library/Caches/pypoetry/virtualenvs/django-kttZJNBW-py3.11/lib/python3.11/site-packages/django/db/migrations/operations/models.py", line 96, in database_forwards
    schema_editor.create_model(model)
  File "/Users/arexils/Library/Caches/pypoetry/virtualenvs/django-kttZJNBW-py3.11/lib/python3.11/site-packages/django/db/backends/base/schema.py", line 447, in create_model
    self.execute(sql, params or None)
  File "/Users/arexils/Library/Caches/pypoetry/virtualenvs/django-kttZJNBW-py3.11/lib/python3.11/site-packages/django/db/backends/base/schema.py", line 199, in execute
    cursor.execute(sql, params)
  File "/Users/arexils/Library/Caches/pypoetry/virtualenvs/django-kttZJNBW-py3.11/lib/python3.11/site-packages/django/db/backends/utils.py", line 103, in execute
    return super().execute(sql, params)
           ^^^^^^^^^^^^^^^^^^^^^^^^^^^^
  File "/Users/arexils/Library/Caches/pypoetry/virtualenvs/django-kttZJNBW-py3.11/lib/python3.11/site-packages/django/db/backends/utils.py", line 67, in execute
    return self._execute_with_wrappers(
           ^^^^^^^^^^^^^^^^^^^^^^^^^^^^
  File "/Users/arexils/Library/Caches/pypoetry/virtualenvs/django-kttZJNBW-py3.11/lib/python3.11/site-packages/django/db/backends/utils.py", line 80, in _execute_with_wrappers
    return executor(sql, params, many, context)
           ^^^^^^^^^^^^^^^^^^^^^^^^^^^^^^^^^^^^
  File "/Users/arexils/Library/Caches/pypoetry/virtualenvs/django-kttZJNBW-py3.11/lib/python3.11/site-packages/django/db/backends/utils.py", line 84, in _execute
    with self.db.wrap_database_errors:
  File "/Users/arexils/Library/Caches/pypoetry/virtualenvs/django-kttZJNBW-py3.11/lib/python3.11/site-packages/django/db/utils.py", line 91, in __exit__
    raise dj_exc_value.with_traceback(traceback) from exc_value
  File "/Users/arexils/Library/Caches/pypoetry/virtualenvs/django-kttZJNBW-py3.11/lib/python3.11/site-packages/django/db/backends/utils.py", line 87, in _execute
    return self.cursor.execute(sql)
           ^^^^^^^^^^^^^^^^^^^^^^^^
  File "/Users/arexils/Library/Caches/pypoetry/virtualenvs/django-kttZJNBW-py3.11/lib/python3.11/site-packages/django/db/backends/mysql/base.py", line 75, in execute
    return self.cursor.execute(query, args)
           ^^^^^^^^^^^^^^^^^^^^^^^^^^^^^^^^
  File "/Users/arexils/Library/Caches/pypoetry/virtualenvs/django-kttZJNBW-py3.11/lib/python3.11/site-packages/MySQLdb/cursors.py", line 206, in execute
    res = self._query(query)
          ^^^^^^^^^^^^^^^^^^
  File "/Users/arexils/Library/Caches/pypoetry/virtualenvs/django-kttZJNBW-py3.11/lib/python3.11/site-packages/MySQLdb/cursors.py", line 319, in _query
    db.query(q)
  File "/Users/arexils/Library/Caches/pypoetry/virtualenvs/django-kttZJNBW-py3.11/lib/python3.11/site-packages/MySQLdb/connections.py", line 254, in query
    _mysql.connection.query(self, query)
django.db.utils.OperationalError: (1050, "Table 'account_emailaddress' already exists")
