2022-11-14 13:07:43,693 525 INFO ? odoo.sql_db: Connection to the database failed 
2022-11-14 13:07:43,700 525 INFO ? werkzeug: 207.244.224.70 - - [14/Nov/2022 13:07:43] "GET /favicon.ico HTTP/1.0" 500 - 0 0.000 0.009
2022-11-14 13:07:43,703 525 ERROR ? werkzeug: Error on request:
Traceback (most recent call last):
  File "/usr/local/lib/python3.6/dist-packages/werkzeug/serving.py", line 205, in run_wsgi
    execute(self.server.app)
  File "/usr/local/lib/python3.6/dist-packages/werkzeug/serving.py", line 193, in execute
    application_iter = app(environ, start_response)
  File "/opt/odoo/odoo/odoo/service/server.py", line 436, in app
    return self.app(e, s)
  File "/opt/odoo/odoo/odoo/service/wsgi_server.py", line 142, in application
    return application_unproxied(environ, start_response)
  File "/opt/odoo/odoo/odoo/service/wsgi_server.py", line 117, in application_unproxied
    result = odoo.http.root(environ, start_response)
  File "/opt/odoo/odoo/odoo/http.py", line 1320, in __call__
    return self.dispatch(environ, start_response)
  File "/opt/odoo/odoo/odoo/http.py", line 1293, in __call__
    return self.app(environ, start_wrapped)
  File "/usr/local/lib/python3.6/dist-packages/werkzeug/wsgi.py", line 599, in __call__
    return self.app(environ, start_response)
  File "/opt/odoo/odoo/odoo/http.py", line 1453, in dispatch
    self.setup_db(httprequest)
  File "/opt/odoo/odoo/odoo/http.py", line 1376, in setup_db
    httprequest.session.db = db_monodb(httprequest)
  File "/opt/odoo/odoo/odoo/http.py", line 1537, in db_monodb
    dbs = db_list(True, httprequest)
  File "/opt/odoo/odoo/odoo/http.py", line 1504, in db_list
    dbs = odoo.service.db.list_dbs(force)
  File "/opt/odoo/odoo/odoo/service/db.py", line 375, in list_dbs
    with closing(db.cursor()) as cr:
  File "/opt/odoo/odoo/odoo/sql_db.py", line 657, in cursor
    return Cursor(self.__pool, self.dbname, self.dsn, serialized=serialized)
  File "/opt/odoo/odoo/odoo/sql_db.py", line 171, in __init__
    self._cnx = pool.borrow(dsn)
  File "/opt/odoo/odoo/odoo/sql_db.py", line 540, in _locked
    return fun(self, *args, **kwargs)
  File "/opt/odoo/odoo/odoo/sql_db.py", line 608, in borrow
    **connection_info)
  File "/usr/local/lib/python3.6/dist-packages/psycopg2/__init__.py", line 130, in connect
    conn = _connect(dsn, connection_factory=connection_factory, **kwasync)
psycopg2.OperationalError: could not connect to server: No such file or directory
	Is the server running locally and accepting
	connections on Unix domain socket "/var/run/postgresql/.s.PGSQL.5432"? - - -
