platform linux -- Python 3.10.6, pytest-7.1.2, pluggy-1.0.0
rootdir: /home/lleri/cppbackend
plugins: xprocess-0.20.0, quickcheck-0.9.0
collected 0 items / 1 error

======================================================== ERRORS ========================================================
______________________ ERROR collecting cpp-backend-tests-practicum/tests/test_s03_gen_objects.py ______________________
../.local/lib/python3.10/site-packages/pluggy/_hooks.py:265: in __call__
    return self._hookexec(self.name, self.get_hookimpls(), kwargs, firstresult)
../.local/lib/python3.10/site-packages/pluggy/_manager.py:80: in _hookexec
    return self._inner_hookexec(hook_name, methods, kwargs, firstresult)
../.local/lib/python3.10/site-packages/_pytest/python.py:262: in pytest_pycollect_makeitem
    return list(collector._genfunctions(name, obj))
../.local/lib/python3.10/site-packages/_pytest/python.py:489: in _genfunctions
    self.ihook.pytest_generate_tests.call_extra(methods, dict(metafunc=metafunc))
../.local/lib/python3.10/site-packages/pluggy/_hooks.py:292: in call_extra
    return self(**kwargs)
../.local/lib/python3.10/site-packages/pluggy/_hooks.py:265: in __call__
    return self._hookexec(self.name, self.get_hookimpls(), kwargs, firstresult)
../.local/lib/python3.10/site-packages/pluggy/_manager.py:80: in _hookexec
    return self._inner_hookexec(hook_name, methods, kwargs, firstresult)
../.local/lib/python3.10/site-packages/pytest_quickcheck/plugin.py:113: in pytest_generate_tests
    _set_parameterize(metafunc, _randomize, ann_data_option)
../.local/lib/python3.10/site-packages/pytest_quickcheck/plugin.py:63: in _set_parameterize
    metafunc.parametrize(argname, values)
../.local/lib/python3.10/site-packages/_pytest/python.py:1320: in parametrize
    newcallspec = callspec.setmulti(
../.local/lib/python3.10/site-packages/_pytest/python.py:1125: in setmulti
    raise ValueError(f"duplicate {arg!r}")
E   ValueError: duplicate 'map_id'
=================================================== warnings summary ===================================================
../.local/lib/python3.10/site-packages/pytest_quickcheck/plugin.py:112
  /home/lleri/.local/lib/python3.10/site-packages/pytest_quickcheck/plugin.py:112: PytestDeprecationWarning: A private pytest class or function was used.
    _randomize = Mark("randomize", args, {})

-- Docs: https://docs.pytest.org/en/stable/how-to/capture-warnings.html
-------------------------------- generated xml file: /home/lleri/cppbackend/results.xml --------------------------------
=============================================== short test summary info ================================================
ERROR cpp-backend-tests-practicum/tests/test_s03_gen_objects.py - ValueError: duplicate 'map_id'
!!!!!!!!!!!!!!!!!!!!!!!!!!!!!!!!!!!!!!!! Interrupted: 1 error during collection !!!!!!!!!!!!!!!!!!!!!!!!!!!!!!!!!!!!!!!!
============================================= 1 warning, 1 error in 0.09s ===================================